<?xml version="1.0" encoding="utf-8"?>
<!-- This URDF was automatically created by SolidWorks to URDF Exporter! Originally created by Stephen Brawner (brawner@gmail.com) 
     Commit Version: 1.6.0-4-g7f85cfe  Build Version: 1.6.7995.38578
     For more information, please see http://wiki.ros.org/sw_urdf_exporter -->
<robot
  name="JAKA-Lumi-sensors-v3">
  <link
    name="base_link">
    <inertial>
      <origin
        xyz="3.57095658215512E-06 0.0438094594610387 0.0731619735136615"
        rpy="0 0 0" />
      <mass
        value="117.497872021732" />
      <inertia
        ixx="3.00670617451833"
        ixy="-5.23402855344243E-05"
        ixz="0.000153120753143614"
        iyy="3.02761964102687"
        iyz="0.0593585142291048"
        izz="4.01740839133865" />
    </inertial>
    <visual>
      <origin
        xyz="0 0 0"
        rpy="0 0 0" />
      <geometry>
        <mesh
          filename="package://JAKA-Lumi-sensors-v3/meshes/base_link.STL" />
      </geometry>
      <material
        name="">
        <color
          rgba="0.898039215686275 0.917647058823529 0.929411764705882 1" />
      </material>
    </visual>
    <collision>
      <origin
        xyz="0 0 0"
        rpy="0 0 0" />
      <geometry>
        <mesh
          filename="package://JAKA-Lumi-sensors-v3/meshes/base_link.STL" />
      </geometry>
    </collision>
  </link>
  <link
    name="wheel_r">
    <inertial>
      <origin
        xyz="0 -1.38777878078145E-17 -2.77555756156289E-17"
        rpy="0 0 0" />
      <mass
        value="0.941042738950082" />
      <inertia
        ixx="0.00170499901767243"
        ixy="-7.83036536159823E-51"
        ixz="-3.93685896742917E-35"
        iyy="0.00170499901767243"
        iyz="-1.70860751235549E-36"
        izz="0.00311129672944552" />
    </inertial>
    <visual>
      <origin
        xyz="0 0 0"
        rpy="0 0 0" />
      <geometry>
        <mesh
          filename="package://JAKA-Lumi-sensors-v3/meshes/wheel_r.STL" />
      </geometry>
      <material
        name="">
        <color
          rgba="0.792156862745098 0.819607843137255 0.933333333333333 1" />
      </material>
    </visual>
    <collision>
      <origin
        xyz="0 0 0"
        rpy="0 0 0" />
      <geometry>
        <mesh
          filename="package://JAKA-Lumi-sensors-v3/meshes/wheel_r.STL" />
      </geometry>
    </collision>
  </link>
  <joint
    name="w_r"
    type="continuous">
    <origin
      xyz="-0.1793 0.050006 -0.2071"
      rpy="0 1.5708 0" />
    <parent
      link="base_link" />
    <child
      link="wheel_r" />
    <axis
      xyz="0 0 1" />
  </joint>
  <link
    name="wheel_l">
    <inertial>
      <origin
        xyz="5.55111512312578E-17 0 -5.55111512312578E-17"
        rpy="0 0 0" />
      <mass
        value="0.941042738950082" />
      <inertia
        ixx="0.00170499901767243"
        ixy="2.08809742975953E-50"
        ixz="7.9632295469293E-35"
        iyy="0.00170499901767243"
        iyz="-1.70860751235549E-36"
        izz="0.00311129672944551" />
    </inertial>
    <visual>
      <origin
        xyz="0 0 0"
        rpy="0 0 0" />
      <geometry>
        <mesh
          filename="package://JAKA-Lumi-sensors-v3/meshes/wheel_l.STL" />
      </geometry>
      <material
        name="">
        <color
          rgba="0.792156862745098 0.819607843137255 0.933333333333333 1" />
      </material>
    </visual>
    <collision>
      <origin
        xyz="0 0 0"
        rpy="0 0 0" />
      <geometry>
        <mesh
          filename="package://JAKA-Lumi-sensors-v3/meshes/wheel_l.STL" />
      </geometry>
    </collision>
  </link>
  <joint
    name="w_l"
    type="continuous">
    <origin
      xyz="0.1793 0.050006 -0.2071"
      rpy="0 1.5708 0" />
    <parent
      link="base_link" />
    <child
      link="wheel_l" />
    <axis
      xyz="0 0 1" />
  </joint>
  <link
    name="link_1">
    <inertial>
      <origin
        xyz="0 0 -0.151"
        rpy="0 0 0" />
      <mass
        value="14.2347501496821" />
      <inertia
        ixx="0.254522077593032"
        ixy="1.40946576508768E-50"
        ixz="2.26754525837298E-33"
        iyy="0.254522077593032"
        iyz="-3.78389053889462E-34"
        izz="0.0264837526534835" />
    </inertial>
    <visual>
      <origin
        xyz="0 0 0"
        rpy="0 0 0" />
      <geometry>
        <mesh
          filename="package://JAKA-Lumi-sensors-v3/meshes/link_1.STL" />
      </geometry>
      <material
        name="">
        <color
          rgba="0.898039215686275 0.917647058823529 0.929411764705882 1" />
      </material>
    </visual>
    <collision>
      <origin
        xyz="0 0 0"
        rpy="0 0 0" />
      <geometry>
        <mesh
          filename="package://JAKA-Lumi-sensors-v3/meshes/link_1.STL" />
      </geometry>
    </collision>
  </link>
  <joint
    name="l_1"
    type="prismatic">
    <origin
      xyz="0 0 0.565"
      rpy="0 0 0" />
    <parent
      link="base_link" />
    <child
      link="link_1" />
    <axis
      xyz="0 0 1" />
    <limit
      lower="0"
      upper="0.4"
      effort="0"
      velocity="0" />
  </joint>
  <link
    name="link_2">
    <inertial>
      <origin
        xyz="-0.00510085608125199 2.76030308702102E-05 0.154933599644375"
        rpy="0 0 0" />
      <mass
        value="4.72336584565363" />
      <inertia
        ixx="0.0504292282245267"
        ixy="-2.72921337177587E-05"
        ixz="-0.00163934802494906"
        iyy="0.0549230312480384"
        iyz="1.85293969295227E-05"
        izz="0.0134598340945887" />
    </inertial>
    <visual>
      <origin
        xyz="0 0 0"
        rpy="0 0 0" />
      <geometry>
        <mesh
          filename="package://JAKA-Lumi-sensors-v3/meshes/link_2.STL" />
      </geometry>
      <material
        name="">
        <color
          rgba="0.792156862745098 0.819607843137255 0.933333333333333 1" />
      </material>
    </visual>
    <collision>
      <origin
        xyz="0 0 0"
        rpy="0 0 0" />
      <geometry>
        <mesh
          filename="package://JAKA-Lumi-sensors-v3/meshes/link_2.STL" />
      </geometry>
    </collision>
  </link>
  <joint
    name="l_2"
    type="revolute">
    <origin
      xyz="0 0 0.0745"
      rpy="0 0 0" />
    <parent
      link="link_1" />
    <child
      link="link_2" />
    <axis
      xyz="0 0 1" />
    <limit
      lower="-2.7925"
      upper="2.7925"
      effort="0"
      velocity="0" />
  </joint>
  <link
    name="link_3">
    <inertial>
      <origin
        xyz="-0.0025460222142763 1.29838654411296E-08 0.0487080488190528"
        rpy="0 0 0" />
      <mass
        value="1.2679984054123" />
      <inertia
        ixx="0.00113364918039248"
        ixy="-8.90052173790371E-10"
        ixz="1.06284029103091E-05"
        iyy="0.00139294470935827"
        iyz="1.94125318630103E-09"
        izz="0.00124029626232309" />
    </inertial>
    <visual>
      <origin
        xyz="0 0 0"
        rpy="0 0 0" />
      <geometry>
        <mesh
          filename="package://JAKA-Lumi-sensors-v3/meshes/link_3.STL" />
      </geometry>
      <material
        name="">
        <color
          rgba="0.898039215686275 0.917647058823529 0.929411764705882 1" />
      </material>
    </visual>
    <collision>
      <origin
        xyz="0 0 0"
        rpy="0 0 0" />
      <geometry>
        <mesh
          filename="package://JAKA-Lumi-sensors-v3/meshes/link_3.STL" />
      </geometry>
    </collision>
  </link>
  <joint
    name="l_3"
    type="revolute">
    <origin
      xyz="0 0 0.3465"
      rpy="0 0 0" />
    <parent
      link="link_2" />
    <child
      link="link_3" />
    <axis
      xyz="0 0 1" />
    <limit
      lower="-3.1415"
      upper="3.1415"
      effort="0"
      velocity="0" />
  </joint>
  <link
    name="link_4">
    <inertial>
      <origin
        xyz="-0.0356340059910656 0.00952703677544092 0.000354991202713484"
        rpy="0 0 0" />
      <mass
        value="0.508357180113433" />
      <inertia
        ixx="0.00217082376630039"
        ixy="-2.42229896931147E-06"
        ixz="-3.02744570630276E-05"
        iyy="0.00182936367129821"
        iyz="4.21377110079457E-06"
        izz="0.00133450978767258" />
    </inertial>
    <visual>
      <origin
        xyz="0 0 0"
        rpy="0 0 0" />
      <geometry>
        <mesh
          filename="package://JAKA-Lumi-sensors-v3/meshes/link_4.STL" />
      </geometry>
      <material
        name="">
        <color
          rgba="0.792156862745098 0.819607843137255 0.933333333333333 1" />
      </material>
    </visual>
    <collision>
      <origin
        xyz="0 0 0"
        rpy="0 0 0" />
      <geometry>
        <mesh
          filename="package://JAKA-Lumi-sensors-v3/meshes/link_4.STL" />
      </geometry>
    </collision>
  </link>
  <joint
    name="l_4"
    type="revolute">
    <origin
      xyz="0 0 0.052"
      rpy="0 1.5708 0" />
    <parent
      link="link_3" />
    <child
      link="link_4" />
    <axis
      xyz="0 0 1" />
    <limit
      lower="-0.0872"
      upper="0.6108"
      effort="0"
      velocity="0" />
  </joint>
  <link
    name="Camera3_Link">
    <inertial>
      <origin
        xyz="5.68892124458431E-05 -2.63392011503605E-05 0.012942735535695"
        rpy="0 0 0" />
      <mass
        value="0.0875979434243871" />
      <inertia
        ixx="1.06602949918824E-05"
        ixy="-8.54998727243587E-08"
        ixz="-5.78556215603225E-08"
        iyy="0.00010643284507406"
        iyz="9.93797837095681E-09"
        izz="0.000107381008142404" />
    </inertial>
    <visual>
      <origin
        xyz="0 0 0"
        rpy="0 0 0" />
      <geometry>
        <mesh
          filename="package://JAKA-Lumi-sensors-v3/meshes/Camera3_Link.STL" />
      </geometry>
      <material
        name="">
        <color
          rgba="0.792156862745098 0.819607843137255 0.933333333333333 1" />
      </material>
    </visual>
    <collision>
      <origin
        xyz="0 0 0"
        rpy="0 0 0" />
      <geometry>
        <mesh
          filename="package://JAKA-Lumi-sensors-v3/meshes/Camera3_Link.STL" />
      </geometry>
    </collision>
  </link>
  <joint
    name="cm3_l"
    type="fixed">
    <origin
      xyz="-0.0552 -0.0665 -0.001"
      rpy="-1.5708 -1.5708 0" />
    <parent
      link="link_4" />
    <child
      link="Camera3_Link" />
    <axis
      xyz="0 0 0" />
  </joint>
  <link
    name="link_a1">
    <inertial>
      <origin
        xyz="-1.9998511011643E-06 0.0134079971471797 0.0943686061195934"
        rpy="0 0 0" />
      <mass
        value="1.35363412771609" />
      <inertia
        ixx="0.00550421009964208"
        ixy="9.79122039100754E-08"
        ixz="2.49435588815162E-08"
        iyy="0.00543503119641918"
        iyz="-0.000690462717635347"
        izz="0.00167462250691422" />
    </inertial>
    <visual>
      <origin
        xyz="0 0 0"
        rpy="0 0 0" />
      <geometry>
        <mesh
          filename="package://JAKA-Lumi-sensors-v3/meshes/link_a1.STL" />
      </geometry>
      <material
        name="">
        <color
          rgba="1 1 1 1" />
      </material>
    </visual>
    <collision>
      <origin
        xyz="0 0 0"
        rpy="0 0 0" />
      <geometry>
        <mesh
          filename="package://JAKA-Lumi-sensors-v3/meshes/link_a1.STL" />
      </geometry>
    </collision>
  </link>
  <joint
    name="l_a1"
    type="revolute">
    <origin
      xyz="-0.104 0 0.069"
      rpy="3.1416 1.5708 0" />
    <parent
      link="link_2" />
    <child
      link="link_a1" />
    <axis
      xyz="0 0 1" />
    <limit
      lower="-6.2831"
      upper="6.2831"
      effort="0"
      velocity="0" />
  </joint>
  <link
    name="link_a2">
    <inertial>
      <origin
        xyz="0.090605416923298 -2.58600093649974E-06 -0.00609952306741931"
        rpy="0 0 0" />
      <mass
        value="1.13725613291731" />
      <inertia
        ixx="0.00215009827923876"
        ixy="8.33869649445781E-07"
        ixz="0.00254380393250188"
        iyy="0.00820239963405526"
        iyz="-4.4243055112101E-07"
        izz="0.00725300805967666" />
    </inertial>
    <visual>
      <origin
        xyz="0 0 0"
        rpy="0 0 0" />
      <geometry>
        <mesh
          filename="package://JAKA-Lumi-sensors-v3/meshes/link_a2.STL" />
      </geometry>
      <material
        name="">
        <color
          rgba="1 1 1 1" />
      </material>
    </visual>
    <collision>
      <origin
        xyz="0 0 0"
        rpy="0 0 0" />
      <geometry>
        <mesh
          filename="package://JAKA-Lumi-sensors-v3/meshes/link_a2.STL" />
      </geometry>
    </collision>
  </link>
  <joint
    name="l_a2"
    type="revolute">
    <origin
      xyz="0 -0.0165 0.156"
      rpy="1.57079632679489 -1.5707963267949 0" />
    <parent
      link="link_a1" />
    <child
      link="link_a2" />
    <axis
      xyz="0 0 1" />
    <limit
      lower="-2.1816"
      upper="2.1816"
      effort="0"
      velocity="0" />
  </joint>
  <link
    name="link_a3">
    <inertial>
      <origin
        xyz="0.0420860444220137 2.83552794133612E-07 0.0309278894752134"
        rpy="0 0 0" />
      <mass
        value="0.81274798684902" />
      <inertia
        ixx="0.000704665343337443"
        ixy="-8.97697298056851E-09"
        ixz="0.000222641185973676"
        iyy="0.00221943524795946"
        iyz="1.40081838032314E-08"
        izz="0.00212284072119055" />
    </inertial>
    <visual>
      <origin
        xyz="0 0 0"
        rpy="0 0 0" />
      <geometry>
        <mesh
          filename="package://JAKA-Lumi-sensors-v3/meshes/link_a3.STL" />
      </geometry>
      <material
        name="">
        <color
          rgba="1 1 1 1" />
      </material>
    </visual>
    <collision>
      <origin
        xyz="0 0 0"
        rpy="0 0 0" />
      <geometry>
        <mesh
          filename="package://JAKA-Lumi-sensors-v3/meshes/link_a3.STL" />
      </geometry>
    </collision>
  </link>
  <joint
    name="l_a3"
    type="revolute">
    <origin
      xyz="0.21 0 -0.029"
      rpy="0 0 0" />
    <parent
      link="link_a2" />
    <child
      link="link_a3" />
    <axis
      xyz="0 0 1" />
    <limit
      lower="-2.2689"
      upper="2.2689"
      effort="0"
      velocity="0" />
  </joint>
  <link
    name="link_a4">
    <inertial>
      <origin
        xyz="5.25973461562579E-06 -0.0259459115704968 0.0452714391339665"
        rpy="0 0 0" />
      <mass
        value="0.308941204464269" />
      <inertia
        ixx="0.000485737318642283"
        ixy="1.50755095959191E-08"
        ixz="2.19693443133857E-08"
        iyy="0.000466355171348267"
        iyz="0.000110728922271964"
        izz="0.000234923681068276" />
    </inertial>
    <visual>
      <origin
        xyz="0 0 0"
        rpy="0 0 0" />
      <geometry>
        <mesh
          filename="package://JAKA-Lumi-sensors-v3/meshes/link_a4.STL" />
      </geometry>
      <material
        name="">
        <color
          rgba="1 1 1 1" />
      </material>
    </visual>
    <collision>
      <origin
        xyz="0 0 0"
        rpy="0 0 0" />
      <geometry>
        <mesh
          filename="package://JAKA-Lumi-sensors-v3/meshes/link_a4.STL" />
      </geometry>
    </collision>
  </link>
  <joint
    name="l_a4"
    type="revolute">
    <origin
      xyz="0.1303 0 0.0185"
      rpy="-1.5708 0 -1.5708" />
    <parent
      link="link_a3" />
    <child
      link="link_a4" />
    <axis
      xyz="0 0 1" />
    <limit
      lower="-6.2831"
      upper="6.2831"
      effort="0"
      velocity="0" />
  </joint>
  <link
    name="link_a5">
    <inertial>
      <origin
        xyz="-0.0445527751967654 8.72515785954597E-06 0.0283178074848019"
        rpy="0 0 0" />
      <mass
        value="0.691485853906912" />
      <inertia
        ixx="0.00053587217476237"
        ixy="-1.66785104800889E-07"
        ixz="-0.000165180730911934"
        iyy="0.00167662010209616"
        iyz="4.52790643374491E-08"
        izz="0.00160760235435603" />
    </inertial>
    <visual>
      <origin
        xyz="0 0 0"
        rpy="0 0 0" />
      <geometry>
        <mesh
          filename="package://JAKA-Lumi-sensors-v3/meshes/link_a5.STL" />
      </geometry>
      <material
        name="">
        <color
          rgba="1 1 1 1" />
      </material>
    </visual>
    <collision>
      <origin
        xyz="0 0 0"
        rpy="0 0 0" />
      <geometry>
        <mesh
          filename="package://JAKA-Lumi-sensors-v3/meshes/link_a5.STL" />
      </geometry>
    </collision>
  </link>
  <joint
    name="l_a5"
    type="revolute">
    <origin
      xyz="0 -0.01805 0.0802"
      rpy="-1.5708 1.5708 0" />
    <parent
      link="link_a4" />
    <child
      link="link_a5" />
    <axis
      xyz="0 0 1" />
    <limit
      lower="-2.0943"
      upper="2.0943"
      effort="0"
      velocity="0" />
  </joint>
  <link
    name="link_a6">
    <inertial>
      <origin
        xyz="3.24059162115642E-05 -2.59128758312438E-05 0.0157071301866493"
        rpy="0 0 0" />
      <mass
        value="0.147762214293587" />
      <inertia
        ixx="6.82806654260406E-05"
        ixy="-1.88579213356883E-07"
        ixz="1.03022750296876E-07"
        iyy="6.73993556738908E-05"
        iyz="4.77520867533898E-08"
        izz="0.000105059848809307" />
    </inertial>
    <visual>
      <origin
        xyz="0 0 0"
        rpy="0 0 0" />
      <geometry>
        <mesh
          filename="package://JAKA-Lumi-sensors-v3/meshes/link_a6.STL" />
      </geometry>
      <material
        name="">
        <color
          rgba="1 1 1 1" />
      </material>
    </visual>
    <collision>
      <origin
        xyz="0 0 0"
        rpy="0 0 0" />
      <geometry>
        <mesh
          filename="package://JAKA-Lumi-sensors-v3/meshes/link_a6.STL" />
      </geometry>
    </collision>
  </link>
  <joint
    name="l_a6"
    type="revolute">
    <origin
      xyz="-0.1233 0 0.01805"
      rpy="1.5708 0 -1.5708" />
    <parent
      link="link_a5" />
    <child
      link="link_a6" />
    <axis
      xyz="0 0 1" />
    <limit
      lower="-6.2831"
      upper="6.2831"
      effort="0"
      velocity="0" />
  </joint>
  <link
    name="link_at">
    <inertial>
      <origin
        xyz="0 -6.93889390390723E-18 -0.001"
        rpy="0 0 0" />
      <mass
        value="0.00155862265526224" />
      <inertia
        ixx="9.71784989903346E-08"
        ixy="-1.09121277893181E-40"
        ixz="-2.82308475359693E-24"
        iyy="9.71784989903346E-08"
        iyz="2.4437407093716E-25"
        izz="1.93317916210494E-07" />
    </inertial>
    <visual>
      <origin
        xyz="0 0 0"
        rpy="0 0 0" />
      <geometry>
        <mesh
          filename="package://JAKA-Lumi-sensors-v3/meshes/link_at.STL" />
      </geometry>
      <material
        name="">
        <color
          rgba="0.792156862745098 0.819607843137255 0.933333333333333 1" />
      </material>
    </visual>
    <collision>
      <origin
        xyz="0 0 0"
        rpy="0 0 0" />
      <geometry>
        <mesh
          filename="package://JAKA-Lumi-sensors-v3/meshes/link_at.STL" />
      </geometry>
    </collision>
  </link>
  <joint
    name="l_at"
    type="fixed">
    <origin
      xyz="0 0 0.0359999999999999"
      rpy="0 0 0" />
    <parent
      link="link_a6" />
    <child
      link="link_at" />
    <axis
      xyz="0 0 0" />
  </joint>
  <link
    name="Camera2_Link">
    <inertial>
      <origin
        xyz="-0.000143110787554801 -0.013057264464305 2.63392011492503E-05"
        rpy="0 0 0" />
      <mass
        value="0.0875979434243874" />
      <inertia
        ixx="1.06602949918825E-05"
        ixy="-5.78556215601044E-08"
        ixz="8.54998727241383E-08"
        iyy="0.000107381008142404"
        iyz="-9.9379783709596E-09"
        izz="0.00010643284507406" />
    </inertial>
    <visual>
      <origin
        xyz="0 0 0"
        rpy="0 0 0" />
      <geometry>
        <mesh
          filename="package://JAKA-Lumi-sensors-v3/meshes/Camera2_Link.STL" />
      </geometry>
      <material
        name="">
        <color
          rgba="0.792156862745098 0.819607843137255 0.933333333333333 1" />
      </material>
    </visual>
    <collision>
      <origin
        xyz="0 0 0"
        rpy="0 0 0" />
      <geometry>
        <mesh
          filename="package://JAKA-Lumi-sensors-v3/meshes/Camera2_Link.STL" />
      </geometry>
    </collision>
  </link>
  <joint
    name="cm2_l"
    type="fixed">
    <origin
      xyz="0.1257 0.011 0.0287"
      rpy="0 0 0" />
    <parent
      link="link_2" />
    <child
      link="Camera2_Link" />
    <axis
      xyz="0 0 0" />
  </joint>
  <link
    name="Radar_Link">
    <inertial>
      <origin
        xyz="0 0 0.0184787735849057"
        rpy="0 0 0" />
      <mass
        value="0.0693768377667744" />
      <inertia
        ixx="1.85319292807384E-05"
        ixy="-5.83702121930894E-25"
        ixz="1.92987550216075E-21"
        iyy="1.85319292807384E-05"
        iyz="4.02294525350527E-25"
        izz="1.95171443604265E-05" />
    </inertial>
    <visual>
      <origin
        xyz="0 0 0"
        rpy="0 0 0" />
      <geometry>
        <mesh
          filename="package://JAKA-Lumi-sensors-v3/meshes/Radar_Link.STL" />
      </geometry>
      <material
        name="">
        <color
          rgba="0.792156862745098 0.819607843137255 0.933333333333333 1" />
      </material>
    </visual>
    <collision>
      <origin
        xyz="0 0 0"
        rpy="0 0 0" />
      <geometry>
        <mesh
          filename="package://JAKA-Lumi-sensors-v3/meshes/Radar_Link.STL" />
      </geometry>
    </collision>
  </link>
  <joint
    name="radar_l"
    type="fixed">
    <origin
      xyz="0 -0.126 -0.085"
      rpy="0 0 0" />
    <parent
      link="base_link" />
    <child
      link="Radar_Link" />
    <axis
      xyz="0 0 0" />
  </joint>
  <link
    name="Camera1_Link">
    <inertial>
      <origin
        xyz="0.00233337804349315 -9.79771819231701E-15 -0.0070004023915114"
        rpy="0 0 0" />
      <mass
        value="0.0115484510006475" />
      <inertia
        ixx="3.5863073748889E-07"
        ixy="-4.49986253228847E-22"
        ixz="1.15461272938505E-08"
        iyy="4.75824187174715E-06"
        iyz="6.35274710440725E-22"
        izz="4.74543151710746E-06" />
    </inertial>
    <visual>
      <origin
        xyz="0 0 0"
        rpy="0 0 0" />
      <geometry>
        <mesh
          filename="package://JAKA-Lumi-sensors-v3/meshes/Camera1_Link.STL" />
      </geometry>
      <material
        name="">
        <color
          rgba="0.792156862745098 0.819607843137255 0.933333333333333 1" />
      </material>
    </visual>
    <collision>
      <origin
        xyz="0 0 0"
        rpy="0 0 0" />
      <geometry>
        <mesh
          filename="package://JAKA-Lumi-sensors-v3/meshes/Camera1_Link.STL" />
      </geometry>
    </collision>
  </link>
  <joint
    name="cm1_l"
    type="fixed">
    <origin
      xyz="0.0029992 -0.19083 -0.12002"
      rpy="-0.66323 0 3.1416" />
    <parent
      link="base_link" />
    <child
      link="Camera1_Link" />
    <axis
      xyz="0 0 0" />
  </joint>
  <link
    name="pw1_Link1">
    <inertial>
      <origin
        xyz="1.8964053383197E-09 -1.39882894156784E-09 0.0424268830920688"
        rpy="0 0 0" />
      <mass
        value="0.0328598949214225" />
      <inertia
        ixx="1.66641395892168E-05"
        ixy="2.62544768904264E-07"
        ixz="4.06684164776544E-13"
        iyy="1.49942324509333E-05"
        iyz="-2.82596433297499E-13"
        izz="3.75003558239013E-06" />
    </inertial>
    <visual>
      <origin
        xyz="0 0 0"
        rpy="0 0 0" />
      <geometry>
        <mesh
          filename="package://JAKA-Lumi-sensors-v3/meshes/pw1_Link1.STL" />
      </geometry>
      <material
        name="">
        <color
          rgba="0.792156862745098 0.819607843137255 0.933333333333333 1" />
      </material>
    </visual>
    <collision>
      <origin
        xyz="0 0 0"
        rpy="0 0 0" />
      <geometry>
        <mesh
          filename="package://JAKA-Lumi-sensors-v3/meshes/pw1_Link1.STL" />
      </geometry>
    </collision>
  </link>
  <joint
    name="pw1_1"
    type="continuous">
    <origin
      xyz="-0.1625 0.2125 -0.1964"
      rpy="3.1416 0 0" />
    <parent
      link="base_link" />
    <child
      link="pw1_Link1" />
    <axis
      xyz="0 0 1" />
  </joint>
  <link
    name="pw1_Link2">
    <inertial>
      <origin
        xyz="-5.55111512312578E-17 1.11022302462516E-16 -1.38777878078145E-17"
        rpy="0 0 0" />
      <mass
        value="0.227276040857673" />
      <inertia
        ixx="0.00012938374626319"
        ixy="-5.97733185760256E-21"
        ixz="1.41941779328965E-21"
        iyy="0.00012938374626319"
        iyz="-1.6940658945086E-21"
        izz="0.000158274748324804" />
    </inertial>
    <visual>
      <origin
        xyz="0 0 0"
        rpy="0 0 0" />
      <geometry>
        <mesh
          filename="package://JAKA-Lumi-sensors-v3/meshes/pw1_Link2.STL" />
      </geometry>
      <material
        name="">
        <color
          rgba="0.792156862745098 0.819607843137255 0.933333333333333 1" />
      </material>
    </visual>
    <collision>
      <origin
        xyz="0 0 0"
        rpy="0 0 0" />
      <geometry>
        <mesh
          filename="package://JAKA-Lumi-sensors-v3/meshes/pw1_Link2.STL" />
      </geometry>
    </collision>
  </link>
  <joint
    name="pw1_2"
    type="continuous">
    <origin
      xyz="0 0 0.0552"
      rpy="0.15233 -1.5708 0" />
    <parent
      link="pw1_Link1" />
    <child
      link="pw1_Link2" />
    <axis
      xyz="0 0 1" />
  </joint>
  <link
    name="pw2_Link1">
    <inertial>
      <origin
        xyz="-8.95573559756002E-10 2.17968404436775E-09 0.0424268830920688"
        rpy="0 0 0" />
      <mass
        value="0.0328598949214225" />
      <inertia
        ixx="1.64475986017118E-05"
        ixy="-6.19389293719969E-07"
        ixz="-2.01073404590596E-13"
        iyy="1.52107734384383E-05"
        iyz="4.52572921378609E-13"
        izz="3.75003558239014E-06" />
    </inertial>
    <visual>
      <origin
        xyz="0 0 0"
        rpy="0 0 0" />
      <geometry>
        <mesh
          filename="package://JAKA-Lumi-sensors-v3/meshes/pw2_Link1.STL" />
      </geometry>
      <material
        name="">
        <color
          rgba="0.792156862745098 0.819607843137255 0.933333333333333 1" />
      </material>
    </visual>
    <collision>
      <origin
        xyz="0 0 0"
        rpy="0 0 0" />
      <geometry>
        <mesh
          filename="package://JAKA-Lumi-sensors-v3/meshes/pw2_Link1.STL" />
      </geometry>
    </collision>
  </link>
  <joint
    name="pw2_1"
    type="continuous">
    <origin
      xyz="0.1625 0.2125 -0.1964"
      rpy="3.1416 0 0" />
    <parent
      link="base_link" />
    <child
      link="pw2_Link1" />
    <axis
      xyz="0 0 1" />
  </joint>
  <link
    name="pw2_Link2">
    <inertial>
      <origin
        xyz="5.55111512312578E-17 -5.27355936696949E-16 0"
        rpy="0 0 0" />
      <mass
        value="0.227276040857673" />
      <inertia
        ixx="0.000129383746263189"
        ixy="-2.13087103829017E-21"
        ixz="-1.71951315608427E-20"
        iyy="0.000129383746263189"
        iyz="-6.7762635780344E-21"
        izz="0.000158274748324804" />
    </inertial>
    <visual>
      <origin
        xyz="0 0 0"
        rpy="0 0 0" />
      <geometry>
        <mesh
          filename="package://JAKA-Lumi-sensors-v3/meshes/pw2_Link2.STL" />
      </geometry>
      <material
        name="">
        <color
          rgba="0.792156862745098 0.819607843137255 0.933333333333333 1" />
      </material>
    </visual>
    <collision>
      <origin
        xyz="0 0 0"
        rpy="0 0 0" />
      <geometry>
        <mesh
          filename="package://JAKA-Lumi-sensors-v3/meshes/pw2_Link2.STL" />
      </geometry>
    </collision>
  </link>
  <joint
    name="pw2_2"
    type="continuous">
    <origin
      xyz="0 0 0.0552"
      rpy="2.7485 1.5708 0" />
    <parent
      link="pw2_Link1" />
    <child
      link="pw2_Link2" />
    <axis
      xyz="0 0 1" />
  </joint>
  <link
    name="pw3_Link1">
    <inertial>
      <origin
        xyz="-8.95573670778305E-10 2.17968410681779E-09 0.0424268830920688"
        rpy="0 0 0" />
      <mass
        value="0.0328598949214225" />
      <inertia
        ixx="1.64475986017118E-05"
        ixy="-6.19389293719968E-07"
        ixz="-2.01073407995355E-13"
        iyy="1.52107734384383E-05"
        iyz="4.52572912857131E-13"
        izz="3.75003558239014E-06" />
    </inertial>
    <visual>
      <origin
        xyz="0 0 0"
        rpy="0 0 0" />
      <geometry>
        <mesh
          filename="package://JAKA-Lumi-sensors-v3/meshes/pw3_Link1.STL" />
      </geometry>
      <material
        name="">
        <color
          rgba="0.792156862745098 0.819607843137255 0.933333333333333 1" />
      </material>
    </visual>
    <collision>
      <origin
        xyz="0 0 0"
        rpy="0 0 0" />
      <geometry>
        <mesh
          filename="package://JAKA-Lumi-sensors-v3/meshes/pw3_Link1.STL" />
      </geometry>
    </collision>
  </link>
  <joint
    name="pw3_1"
    type="continuous">
    <origin
      xyz="-0.1625 -0.1125 -0.1964"
      rpy="3.1416 0 0" />
    <parent
      link="base_link" />
    <child
      link="pw3_Link1" />
    <axis
      xyz="0 0 1" />
  </joint>
  <link
    name="pw3_Link2">
    <inertial>
      <origin
        xyz="-5.55111512312578E-17 5.55111512312578E-17 5.55111512312578E-17"
        rpy="0 0 0" />
      <mass
        value="0.227276040857673" />
      <inertia
        ixx="0.00012938374626319"
        ixy="-3.0448656413053E-21"
        ixz="1.37324426331394E-21"
        iyy="0.00012938374626319"
        iyz="0"
        izz="0.000158274748324804" />
    </inertial>
    <visual>
      <origin
        xyz="0 0 0"
        rpy="0 0 0" />
      <geometry>
        <mesh
          filename="package://JAKA-Lumi-sensors-v3/meshes/pw3_Link2.STL" />
      </geometry>
      <material
        name="">
        <color
          rgba="0.792156862745098 0.819607843137255 0.933333333333333 1" />
      </material>
    </visual>
    <collision>
      <origin
        xyz="0 0 0"
        rpy="0 0 0" />
      <geometry>
        <mesh
          filename="package://JAKA-Lumi-sensors-v3/meshes/pw3_Link2.STL" />
      </geometry>
    </collision>
  </link>
  <joint
    name="pw3_2"
    type="continuous">
    <origin
      xyz="0 0 0.0552"
      rpy="2.7485 1.5708 0" />
    <parent
      link="pw3_Link1" />
    <child
      link="pw3_Link2" />
    <axis
      xyz="0 0 1" />
  </joint>
  <link
    name="pw4_Link1">
    <inertial>
      <origin
        xyz="-8.95573726289456E-10 2.17968409294E-09 0.0424268830920689"
        rpy="0 0 0" />
      <mass
        value="0.0328598949214226" />
      <inertia
        ixx="1.64475986017118E-05"
        ixy="-6.19389293719969E-07"
        ixz="-2.01073406532492E-13"
        iyy="1.52107734384383E-05"
        iyz="4.52572915702944E-13"
        izz="3.75003558239015E-06" />
    </inertial>
    <visual>
      <origin
        xyz="0 0 0"
        rpy="0 0 0" />
      <geometry>
        <mesh
          filename="package://JAKA-Lumi-sensors-v3/meshes/pw4_Link1.STL" />
      </geometry>
      <material
        name="">
        <color
          rgba="0.792156862745098 0.819607843137255 0.933333333333333 1" />
      </material>
    </visual>
    <collision>
      <origin
        xyz="0 0 0"
        rpy="0 0 0" />
      <geometry>
        <mesh
          filename="package://JAKA-Lumi-sensors-v3/meshes/pw4_Link1.STL" />
      </geometry>
    </collision>
  </link>
  <joint
    name="pw4_1"
    type="continuous">
    <origin
      xyz="0.1625 -0.1125 -0.1964"
      rpy="3.1416 0 0" />
    <parent
      link="base_link" />
    <child
      link="pw4_Link1" />
    <axis
      xyz="0 0 1" />
  </joint>
  <link
    name="pw4_Link2">
    <inertial>
      <origin
        xyz="0 2.77555756156289E-17 1.66533453693773E-16"
        rpy="0 0 0" />
      <mass
        value="0.227276040857673" />
      <inertia
        ixx="0.00012938374626319"
        ixy="-1.72359010019817E-21"
        ixz="1.83362964261698E-22"
        iyy="0.00012938374626319"
        iyz="-1.01643953670516E-20"
        izz="0.000158274748324804" />
    </inertial>
    <visual>
      <origin
        xyz="0 0 0"
        rpy="0 0 0" />
      <geometry>
        <mesh
          filename="package://JAKA-Lumi-sensors-v3/meshes/pw4_Link2.STL" />
      </geometry>
      <material
        name="">
        <color
          rgba="0.792156862745098 0.819607843137255 0.933333333333333 1" />
      </material>
    </visual>
    <collision>
      <origin
        xyz="0 0 0"
        rpy="0 0 0" />
      <geometry>
        <mesh
          filename="package://JAKA-Lumi-sensors-v3/meshes/pw4_Link2.STL" />
      </geometry>
    </collision>
  </link>
  <joint
    name="pw4_2"
    type="continuous">
    <origin
      xyz="0 0 0.0552"
      rpy="2.7485 1.5708 0" />
    <parent
      link="pw4_Link1" />
    <child
      link="pw4_Link2" />
    <axis
      xyz="0 0 1" />
  </joint>
</robot>